2023-08-03 15:57:02,440 [ERROR] - An error occurred: Reason: Provided Schema does not match Table crop2cloud:sensor_data.span2nodeB. Cannot add fields (field: _2010B5TDR1823)
Traceback (most recent call last):
  File "c:\Users\bnsoh2\Desktop\venvs\logger_env\Lib\site-packages\google\cloud\bigquery\client.py", line 2486, in load_table_from_file
    response = self._do_multipart_upload(
               ^^^^^^^^^^^^^^^^^^^^^^^^^^
  File "c:\Users\bnsoh2\Desktop\venvs\logger_env\Lib\site-packages\google\cloud\bigquery\client.py", line 3053, in _do_multipart_upload
    response = upload.transmit(
               ^^^^^^^^^^^^^^^^
  File "c:\Users\bnsoh2\Desktop\venvs\logger_env\Lib\site-packages\google\resumable_media\requests\upload.py", line 153, in transmit
    return _request_helpers.wait_and_retry(
           ^^^^^^^^^^^^^^^^^^^^^^^^^^^^^^^^
  File "c:\Users\bnsoh2\Desktop\venvs\logger_env\Lib\site-packages\google\resumable_media\requests\_request_helpers.py", line 155, in wait_and_retry
    response = func()
               ^^^^^^
  File "c:\Users\bnsoh2\Desktop\venvs\logger_env\Lib\site-packages\google\resumable_media\requests\upload.py", line 149, in retriable_request
    self._process_response(result)
  File "c:\Users\bnsoh2\Desktop\venvs\logger_env\Lib\site-packages\google\resumable_media\_upload.py", line 114, in _process_response
    _helpers.require_status_code(response, (http.client.OK,), self._get_status_code)
  File "c:\Users\bnsoh2\Desktop\venvs\logger_env\Lib\site-packages\google\resumable_media\_helpers.py", line 108, in require_status_code
    raise common.InvalidResponse(
google.resumable_media.common.InvalidResponse: ('Request failed with status code', 400, 'Expected one of', <HTTPStatus.OK: 200>)

During handling of the above exception, another exception occurred:

Traceback (most recent call last):
  File "c:\Users\bnsoh2\Desktop\venvs\logger_env\Lib\site-packages\pandas_gbq\gbq.py", line 602, in load_data
    chunks = load.load_chunks(
             ^^^^^^^^^^^^^^^^^
  File "c:\Users\bnsoh2\Desktop\venvs\logger_env\Lib\site-packages\pandas_gbq\load.py", line 243, in load_chunks
    load_parquet(
  File "c:\Users\bnsoh2\Desktop\venvs\logger_env\Lib\site-packages\pandas_gbq\load.py", line 131, in load_parquet
    client.load_table_from_dataframe(
  File "c:\Users\bnsoh2\Desktop\venvs\logger_env\Lib\site-packages\google\cloud\bigquery\client.py", line 2734, in load_table_from_dataframe
    return self.load_table_from_file(
           ^^^^^^^^^^^^^^^^^^^^^^^^^^
  File "c:\Users\bnsoh2\Desktop\venvs\logger_env\Lib\site-packages\google\cloud\bigquery\client.py", line 2490, in load_table_from_file
    raise exceptions.from_http_response(exc.response)
google.api_core.exceptions.BadRequest: 400 POST https://bigquery.googleapis.com/upload/bigquery/v2/projects/crop2cloud/jobs?uploadType=multipart: Provided Schema does not match Table crop2cloud:sensor_data.span2nodeB. Cannot add fields (field: _2010B5TDR1823)

During handling of the above exception, another exception occurred:

Traceback (most recent call last):
  File "c:\Users\bnsoh2\OneDrive - University of Nebraska-Lincoln\Documents\Coding Projects\Datalogger2Cloud\test.py", line 179, in <module>
    update_bigquery(client, dataset_id, table_id, averaged_df)
  File "c:\Users\bnsoh2\OneDrive - University of Nebraska-Lincoln\Documents\Coding Projects\Datalogger2Cloud\test.py", line 100, in update_bigquery
    df.to_gbq(
  File "c:\Users\bnsoh2\Desktop\venvs\logger_env\Lib\site-packages\pandas\core\frame.py", line 2088, in to_gbq
    gbq.to_gbq(
  File "c:\Users\bnsoh2\Desktop\venvs\logger_env\Lib\site-packages\pandas\io\gbq.py", line 215, in to_gbq
    pandas_gbq.to_gbq(
  File "c:\Users\bnsoh2\Desktop\venvs\logger_env\Lib\site-packages\pandas_gbq\gbq.py", line 1220, in to_gbq
    connector.load_data(
  File "c:\Users\bnsoh2\Desktop\venvs\logger_env\Lib\site-packages\pandas_gbq\gbq.py", line 622, in load_data
    self.process_http_error(ex)
  File "c:\Users\bnsoh2\Desktop\venvs\logger_env\Lib\site-packages\pandas_gbq\gbq.py", line 391, in process_http_error
    raise InvalidSchema(f"Reason: {error_message}")
pandas_gbq.gbq.InvalidSchema: Reason: Provided Schema does not match Table crop2cloud:sensor_data.span2nodeB. Cannot add fields (field: _2010B5TDR1823)
2023-08-03 16:07:30,490 [INFO] - 
1 out of 1 rows loaded.
2023-08-04 11:28:02,501 [ERROR] - An error occurred: table sensor_data has no column named _5009B1IRTXX23
Traceback (most recent call last):
  File "c:\Users\bnsoh2\OneDrive - University of Nebraska-Lincoln\Documents\Coding Projects\Datalogger2Cloud\test.py", line 199, in <module>
    averaged_df.to_sql("sensor_data", conn, if_exists="append", index=False)
  File "c:\Users\bnsoh2\Desktop\venvs\logger_env\Lib\site-packages\pandas\core\generic.py", line 2878, in to_sql
    return sql.to_sql(
           ^^^^^^^^^^^
  File "c:\Users\bnsoh2\Desktop\venvs\logger_env\Lib\site-packages\pandas\io\sql.py", line 769, in to_sql
    return pandas_sql.to_sql(
           ^^^^^^^^^^^^^^^^^^
  File "c:\Users\bnsoh2\Desktop\venvs\logger_env\Lib\site-packages\pandas\io\sql.py", line 2379, in to_sql
    return table.insert(chunksize, method)
           ^^^^^^^^^^^^^^^^^^^^^^^^^^^^^^^
  File "c:\Users\bnsoh2\Desktop\venvs\logger_env\Lib\site-packages\pandas\io\sql.py", line 1023, in insert
    num_inserted = exec_insert(conn, keys, chunk_iter)
                   ^^^^^^^^^^^^^^^^^^^^^^^^^^^^^^^^^^^
  File "c:\Users\bnsoh2\Desktop\venvs\logger_env\Lib\site-packages\pandas\io\sql.py", line 2075, in _execute_insert
    conn.executemany(self.insert_statement(num_rows=1), data_list)
sqlite3.OperationalError: table sensor_data has no column named _5009B1IRTXX23
2023-08-04 11:28:42,281 [ERROR] - An error occurred: table sensor_data has no column named _5009B1IRTXX23
Traceback (most recent call last):
  File "c:\Users\bnsoh2\OneDrive - University of Nebraska-Lincoln\Documents\Coding Projects\Datalogger2Cloud\test.py", line 199, in <module>
    averaged_df.to_sql("sensor_data", conn, if_exists="append", index=False)
  File "c:\Users\bnsoh2\Desktop\venvs\logger_env\Lib\site-packages\pandas\core\generic.py", line 2878, in to_sql
    return sql.to_sql(
           ^^^^^^^^^^^
  File "c:\Users\bnsoh2\Desktop\venvs\logger_env\Lib\site-packages\pandas\io\sql.py", line 769, in to_sql
    return pandas_sql.to_sql(
           ^^^^^^^^^^^^^^^^^^
  File "c:\Users\bnsoh2\Desktop\venvs\logger_env\Lib\site-packages\pandas\io\sql.py", line 2379, in to_sql
    return table.insert(chunksize, method)
           ^^^^^^^^^^^^^^^^^^^^^^^^^^^^^^^
  File "c:\Users\bnsoh2\Desktop\venvs\logger_env\Lib\site-packages\pandas\io\sql.py", line 1023, in insert
    num_inserted = exec_insert(conn, keys, chunk_iter)
                   ^^^^^^^^^^^^^^^^^^^^^^^^^^^^^^^^^^^
  File "c:\Users\bnsoh2\Desktop\venvs\logger_env\Lib\site-packages\pandas\io\sql.py", line 2075, in _execute_insert
    conn.executemany(self.insert_statement(num_rows=1), data_list)
sqlite3.OperationalError: table sensor_data has no column named _5009B1IRTXX23
2023-08-04 11:36:12,186 [ERROR] - An error occurred: table sensor_data has no column named _5009B1IRTXX23
Traceback (most recent call last):
  File "c:\Users\bnsoh2\OneDrive - University of Nebraska-Lincoln\Documents\Coding Projects\Datalogger2Cloud\test.py", line 199, in <module>
    averaged_df.to_sql("sensor_data", conn, if_exists="append", index=False)
  File "c:\Users\bnsoh2\Desktop\venvs\logger_env\Lib\site-packages\pandas\core\generic.py", line 2878, in to_sql
    return sql.to_sql(
           ^^^^^^^^^^^
  File "c:\Users\bnsoh2\Desktop\venvs\logger_env\Lib\site-packages\pandas\io\sql.py", line 769, in to_sql
    return pandas_sql.to_sql(
           ^^^^^^^^^^^^^^^^^^
  File "c:\Users\bnsoh2\Desktop\venvs\logger_env\Lib\site-packages\pandas\io\sql.py", line 2379, in to_sql
    return table.insert(chunksize, method)
           ^^^^^^^^^^^^^^^^^^^^^^^^^^^^^^^
  File "c:\Users\bnsoh2\Desktop\venvs\logger_env\Lib\site-packages\pandas\io\sql.py", line 1023, in insert
    num_inserted = exec_insert(conn, keys, chunk_iter)
                   ^^^^^^^^^^^^^^^^^^^^^^^^^^^^^^^^^^^
  File "c:\Users\bnsoh2\Desktop\venvs\logger_env\Lib\site-packages\pandas\io\sql.py", line 2075, in _execute_insert
    conn.executemany(self.insert_statement(num_rows=1), data_list)
sqlite3.OperationalError: table sensor_data has no column named _5009B1IRTXX23
2023-08-04 16:08:09,425 [INFO] - Interrupted by user. Exiting...
2023-08-04 16:12:26,618 [ERROR] - An error occurred: table sensor_data has no column named _5001A1TDR0623_ST
Traceback (most recent call last):
  File "c:\Users\bnsoh2\OneDrive - University of Nebraska-Lincoln\Documents\Coding Projects\Datalogger2Cloud\test.py", line 195, in <module>
    averaged_df.to_sql("sensor_data", conn, if_exists="append", index=False)
  File "c:\Users\bnsoh2\Desktop\venvs\logger_env\Lib\site-packages\pandas\core\generic.py", line 2878, in to_sql
    return sql.to_sql(
           ^^^^^^^^^^^
  File "c:\Users\bnsoh2\Desktop\venvs\logger_env\Lib\site-packages\pandas\io\sql.py", line 769, in to_sql
    return pandas_sql.to_sql(
           ^^^^^^^^^^^^^^^^^^
  File "c:\Users\bnsoh2\Desktop\venvs\logger_env\Lib\site-packages\pandas\io\sql.py", line 2379, in to_sql
    return table.insert(chunksize, method)
           ^^^^^^^^^^^^^^^^^^^^^^^^^^^^^^^
  File "c:\Users\bnsoh2\Desktop\venvs\logger_env\Lib\site-packages\pandas\io\sql.py", line 1023, in insert
    num_inserted = exec_insert(conn, keys, chunk_iter)
                   ^^^^^^^^^^^^^^^^^^^^^^^^^^^^^^^^^^^
  File "c:\Users\bnsoh2\Desktop\venvs\logger_env\Lib\site-packages\pandas\io\sql.py", line 2075, in _execute_insert
    conn.executemany(self.insert_statement(num_rows=1), data_list)
sqlite3.OperationalError: table sensor_data has no column named _5001A1TDR0623_ST
2023-08-04 16:19:10,567 [ERROR] - An error occurred when reading sensor 5001A1TDR0623: ClearCommError failed (PermissionError(13, 'Access is denied.', None, 5))
Traceback (most recent call last):
  File "c:\Users\bnsoh2\OneDrive - University of Nebraska-Lincoln\Documents\Coding Projects\Datalogger2Cloud\test.py", line 155, in <module>
    sensor_values = read_sensor_data(ser1, lock1, sdi_12_address, b"M")
                    ^^^^^^^^^^^^^^^^^^^^^^^^^^^^^^^^^^^^^^^^^^^^^^^^^^^
  File "c:\Users\bnsoh2\OneDrive - University of Nebraska-Lincoln\Documents\Coding Projects\Datalogger2Cloud\test.py", line 76, in read_sensor_data
    sdi_12_line = ser.readline()
                  ^^^^^^^^^^^^^^
  File "c:\Users\bnsoh2\Desktop\venvs\logger_env\Lib\site-packages\serial\serialwin32.py", line 275, in read
    raise SerialException("ClearCommError failed ({!r})".format(ctypes.WinError()))
serial.serialutil.SerialException: ClearCommError failed (PermissionError(13, 'Access is denied.', None, 5))
2023-08-04 16:19:10,567 [ERROR] - An error occurred when reading sensor 5001A1TDR1823: WriteFile failed (PermissionError(13, 'Access is denied.', None, 5))
Traceback (most recent call last):
  File "c:\Users\bnsoh2\OneDrive - University of Nebraska-Lincoln\Documents\Coding Projects\Datalogger2Cloud\test.py", line 155, in <module>
    sensor_values = read_sensor_data(ser1, lock1, sdi_12_address, b"M")
                    ^^^^^^^^^^^^^^^^^^^^^^^^^^^^^^^^^^^^^^^^^^^^^^^^^^^
  File "c:\Users\bnsoh2\OneDrive - University of Nebraska-Lincoln\Documents\Coding Projects\Datalogger2Cloud\test.py", line 73, in read_sensor_data
    ser.write(sdi_12_address + measurement_code + b"!")
  File "c:\Users\bnsoh2\Desktop\venvs\logger_env\Lib\site-packages\serial\serialwin32.py", line 317, in write
    raise SerialException("WriteFile failed ({!r})".format(ctypes.WinError()))
serial.serialutil.SerialException: WriteFile failed (PermissionError(13, 'Access is denied.', None, 5))
2023-08-04 16:19:10,582 [ERROR] - An error occurred when reading sensor 5001A1TDR3023: WriteFile failed (PermissionError(13, 'Access is denied.', None, 5))
Traceback (most recent call last):
  File "c:\Users\bnsoh2\OneDrive - University of Nebraska-Lincoln\Documents\Coding Projects\Datalogger2Cloud\test.py", line 155, in <module>
    sensor_values = read_sensor_data(ser1, lock1, sdi_12_address, b"M")
                    ^^^^^^^^^^^^^^^^^^^^^^^^^^^^^^^^^^^^^^^^^^^^^^^^^^^
  File "c:\Users\bnsoh2\OneDrive - University of Nebraska-Lincoln\Documents\Coding Projects\Datalogger2Cloud\test.py", line 73, in read_sensor_data
    ser.write(sdi_12_address + measurement_code + b"!")
  File "c:\Users\bnsoh2\Desktop\venvs\logger_env\Lib\site-packages\serial\serialwin32.py", line 317, in write
    raise SerialException("WriteFile failed ({!r})".format(ctypes.WinError()))
serial.serialutil.SerialException: WriteFile failed (PermissionError(13, 'Access is denied.', None, 5))
2023-08-04 16:19:10,582 [ERROR] - An error occurred when reading sensor 5001A1TDR4223: WriteFile failed (PermissionError(13, 'Access is denied.', None, 5))
Traceback (most recent call last):
  File "c:\Users\bnsoh2\OneDrive - University of Nebraska-Lincoln\Documents\Coding Projects\Datalogger2Cloud\test.py", line 155, in <module>
    sensor_values = read_sensor_data(ser1, lock1, sdi_12_address, b"M")
                    ^^^^^^^^^^^^^^^^^^^^^^^^^^^^^^^^^^^^^^^^^^^^^^^^^^^
  File "c:\Users\bnsoh2\OneDrive - University of Nebraska-Lincoln\Documents\Coding Projects\Datalogger2Cloud\test.py", line 73, in read_sensor_data
    ser.write(sdi_12_address + measurement_code + b"!")
  File "c:\Users\bnsoh2\Desktop\venvs\logger_env\Lib\site-packages\serial\serialwin32.py", line 317, in write
    raise SerialException("WriteFile failed ({!r})".format(ctypes.WinError()))
serial.serialutil.SerialException: WriteFile failed (PermissionError(13, 'Access is denied.', None, 5))
2023-08-04 16:19:10,582 [ERROR] - An error occurred when reading sensor 5009B1IRTXX23: WriteFile failed (PermissionError(13, 'Access is denied.', None, 5))
Traceback (most recent call last):
  File "c:\Users\bnsoh2\OneDrive - University of Nebraska-Lincoln\Documents\Coding Projects\Datalogger2Cloud\test.py", line 155, in <module>
    sensor_values = read_sensor_data(ser1, lock1, sdi_12_address, b"M")
                    ^^^^^^^^^^^^^^^^^^^^^^^^^^^^^^^^^^^^^^^^^^^^^^^^^^^
  File "c:\Users\bnsoh2\OneDrive - University of Nebraska-Lincoln\Documents\Coding Projects\Datalogger2Cloud\test.py", line 73, in read_sensor_data
    ser.write(sdi_12_address + measurement_code + b"!")
  File "c:\Users\bnsoh2\Desktop\venvs\logger_env\Lib\site-packages\serial\serialwin32.py", line 317, in write
    raise SerialException("WriteFile failed ({!r})".format(ctypes.WinError()))
serial.serialutil.SerialException: WriteFile failed (PermissionError(13, 'Access is denied.', None, 5))
2023-08-04 16:19:10,582 [ERROR] - An error occurred when reading sensor 5009B1TDR0623: WriteFile failed (PermissionError(13, 'Access is denied.', None, 5))
Traceback (most recent call last):
  File "c:\Users\bnsoh2\OneDrive - University of Nebraska-Lincoln\Documents\Coding Projects\Datalogger2Cloud\test.py", line 155, in <module>
    sensor_values = read_sensor_data(ser1, lock1, sdi_12_address, b"M")
                    ^^^^^^^^^^^^^^^^^^^^^^^^^^^^^^^^^^^^^^^^^^^^^^^^^^^
  File "c:\Users\bnsoh2\OneDrive - University of Nebraska-Lincoln\Documents\Coding Projects\Datalogger2Cloud\test.py", line 73, in read_sensor_data
    ser.write(sdi_12_address + measurement_code + b"!")
  File "c:\Users\bnsoh2\Desktop\venvs\logger_env\Lib\site-packages\serial\serialwin32.py", line 317, in write
    raise SerialException("WriteFile failed ({!r})".format(ctypes.WinError()))
serial.serialutil.SerialException: WriteFile failed (PermissionError(13, 'Access is denied.', None, 5))
2023-08-04 16:19:10,593 [ERROR] - An error occurred when reading sensor 5009B1TDR1823: WriteFile failed (PermissionError(13, 'Access is denied.', None, 5))
Traceback (most recent call last):
  File "c:\Users\bnsoh2\OneDrive - University of Nebraska-Lincoln\Documents\Coding Projects\Datalogger2Cloud\test.py", line 155, in <module>
    sensor_values = read_sensor_data(ser1, lock1, sdi_12_address, b"M")
                    ^^^^^^^^^^^^^^^^^^^^^^^^^^^^^^^^^^^^^^^^^^^^^^^^^^^
  File "c:\Users\bnsoh2\OneDrive - University of Nebraska-Lincoln\Documents\Coding Projects\Datalogger2Cloud\test.py", line 73, in read_sensor_data
    ser.write(sdi_12_address + measurement_code + b"!")
  File "c:\Users\bnsoh2\Desktop\venvs\logger_env\Lib\site-packages\serial\serialwin32.py", line 317, in write
    raise SerialException("WriteFile failed ({!r})".format(ctypes.WinError()))
serial.serialutil.SerialException: WriteFile failed (PermissionError(13, 'Access is denied.', None, 5))
2023-08-04 16:19:10,599 [ERROR] - An error occurred when reading sensor 5009B1TDR3023: WriteFile failed (PermissionError(13, 'Access is denied.', None, 5))
Traceback (most recent call last):
  File "c:\Users\bnsoh2\OneDrive - University of Nebraska-Lincoln\Documents\Coding Projects\Datalogger2Cloud\test.py", line 155, in <module>
    sensor_values = read_sensor_data(ser1, lock1, sdi_12_address, b"M")
                    ^^^^^^^^^^^^^^^^^^^^^^^^^^^^^^^^^^^^^^^^^^^^^^^^^^^
  File "c:\Users\bnsoh2\OneDrive - University of Nebraska-Lincoln\Documents\Coding Projects\Datalogger2Cloud\test.py", line 73, in read_sensor_data
    ser.write(sdi_12_address + measurement_code + b"!")
  File "c:\Users\bnsoh2\Desktop\venvs\logger_env\Lib\site-packages\serial\serialwin32.py", line 317, in write
    raise SerialException("WriteFile failed ({!r})".format(ctypes.WinError()))
serial.serialutil.SerialException: WriteFile failed (PermissionError(13, 'Access is denied.', None, 5))
2023-08-04 16:19:10,603 [ERROR] - An error occurred when reading sensor 5009B1TDR4223: WriteFile failed (PermissionError(13, 'Access is denied.', None, 5))
Traceback (most recent call last):
  File "c:\Users\bnsoh2\OneDrive - University of Nebraska-Lincoln\Documents\Coding Projects\Datalogger2Cloud\test.py", line 155, in <module>
    sensor_values = read_sensor_data(ser1, lock1, sdi_12_address, b"M")
                    ^^^^^^^^^^^^^^^^^^^^^^^^^^^^^^^^^^^^^^^^^^^^^^^^^^^
  File "c:\Users\bnsoh2\OneDrive - University of Nebraska-Lincoln\Documents\Coding Projects\Datalogger2Cloud\test.py", line 73, in read_sensor_data
    ser.write(sdi_12_address + measurement_code + b"!")
  File "c:\Users\bnsoh2\Desktop\venvs\logger_env\Lib\site-packages\serial\serialwin32.py", line 317, in write
    raise SerialException("WriteFile failed ({!r})".format(ctypes.WinError()))
serial.serialutil.SerialException: WriteFile failed (PermissionError(13, 'Access is denied.', None, 5))
2023-08-04 16:19:10,605 [ERROR] - An error occurred when reading sensor 5014C1IRTXX23: WriteFile failed (PermissionError(13, 'Access is denied.', None, 5))
Traceback (most recent call last):
  File "c:\Users\bnsoh2\OneDrive - University of Nebraska-Lincoln\Documents\Coding Projects\Datalogger2Cloud\test.py", line 155, in <module>
    sensor_values = read_sensor_data(ser1, lock1, sdi_12_address, b"M")
                    ^^^^^^^^^^^^^^^^^^^^^^^^^^^^^^^^^^^^^^^^^^^^^^^^^^^
  File "c:\Users\bnsoh2\OneDrive - University of Nebraska-Lincoln\Documents\Coding Projects\Datalogger2Cloud\test.py", line 73, in read_sensor_data
    ser.write(sdi_12_address + measurement_code + b"!")
  File "c:\Users\bnsoh2\Desktop\venvs\logger_env\Lib\site-packages\serial\serialwin32.py", line 317, in write
    raise SerialException("WriteFile failed ({!r})".format(ctypes.WinError()))
serial.serialutil.SerialException: WriteFile failed (PermissionError(13, 'Access is denied.', None, 5))
2023-08-04 16:19:10,607 [ERROR] - An error occurred when reading sensor 5014C1TDR0623: WriteFile failed (PermissionError(13, 'Access is denied.', None, 5))
Traceback (most recent call last):
  File "c:\Users\bnsoh2\OneDrive - University of Nebraska-Lincoln\Documents\Coding Projects\Datalogger2Cloud\test.py", line 155, in <module>
    sensor_values = read_sensor_data(ser1, lock1, sdi_12_address, b"M")
                    ^^^^^^^^^^^^^^^^^^^^^^^^^^^^^^^^^^^^^^^^^^^^^^^^^^^
  File "c:\Users\bnsoh2\OneDrive - University of Nebraska-Lincoln\Documents\Coding Projects\Datalogger2Cloud\test.py", line 73, in read_sensor_data
    ser.write(sdi_12_address + measurement_code + b"!")
  File "c:\Users\bnsoh2\Desktop\venvs\logger_env\Lib\site-packages\serial\serialwin32.py", line 317, in write
    raise SerialException("WriteFile failed ({!r})".format(ctypes.WinError()))
serial.serialutil.SerialException: WriteFile failed (PermissionError(13, 'Access is denied.', None, 5))
2023-08-04 16:19:10,607 [ERROR] - An error occurred when reading sensor 5014C1TDR1823: WriteFile failed (PermissionError(13, 'Access is denied.', None, 5))
Traceback (most recent call last):
  File "c:\Users\bnsoh2\OneDrive - University of Nebraska-Lincoln\Documents\Coding Projects\Datalogger2Cloud\test.py", line 155, in <module>
    sensor_values = read_sensor_data(ser1, lock1, sdi_12_address, b"M")
                    ^^^^^^^^^^^^^^^^^^^^^^^^^^^^^^^^^^^^^^^^^^^^^^^^^^^
  File "c:\Users\bnsoh2\OneDrive - University of Nebraska-Lincoln\Documents\Coding Projects\Datalogger2Cloud\test.py", line 73, in read_sensor_data
    ser.write(sdi_12_address + measurement_code + b"!")
  File "c:\Users\bnsoh2\Desktop\venvs\logger_env\Lib\site-packages\serial\serialwin32.py", line 317, in write
    raise SerialException("WriteFile failed ({!r})".format(ctypes.WinError()))
serial.serialutil.SerialException: WriteFile failed (PermissionError(13, 'Access is denied.', None, 5))
2023-08-04 16:19:10,610 [ERROR] - An error occurred when reading sensor 5014C1TDR3023: WriteFile failed (PermissionError(13, 'Access is denied.', None, 5))
Traceback (most recent call last):
  File "c:\Users\bnsoh2\OneDrive - University of Nebraska-Lincoln\Documents\Coding Projects\Datalogger2Cloud\test.py", line 155, in <module>
    sensor_values = read_sensor_data(ser1, lock1, sdi_12_address, b"M")
                    ^^^^^^^^^^^^^^^^^^^^^^^^^^^^^^^^^^^^^^^^^^^^^^^^^^^
  File "c:\Users\bnsoh2\OneDrive - University of Nebraska-Lincoln\Documents\Coding Projects\Datalogger2Cloud\test.py", line 73, in read_sensor_data
    ser.write(sdi_12_address + measurement_code + b"!")
  File "c:\Users\bnsoh2\Desktop\venvs\logger_env\Lib\site-packages\serial\serialwin32.py", line 317, in write
    raise SerialException("WriteFile failed ({!r})".format(ctypes.WinError()))
serial.serialutil.SerialException: WriteFile failed (PermissionError(13, 'Access is denied.', None, 5))
2023-08-04 16:19:10,615 [ERROR] - An error occurred when reading sensor 5014C1TDR4223: WriteFile failed (PermissionError(13, 'Access is denied.', None, 5))
Traceback (most recent call last):
  File "c:\Users\bnsoh2\OneDrive - University of Nebraska-Lincoln\Documents\Coding Projects\Datalogger2Cloud\test.py", line 155, in <module>
    sensor_values = read_sensor_data(ser1, lock1, sdi_12_address, b"M")
                    ^^^^^^^^^^^^^^^^^^^^^^^^^^^^^^^^^^^^^^^^^^^^^^^^^^^
  File "c:\Users\bnsoh2\OneDrive - University of Nebraska-Lincoln\Documents\Coding Projects\Datalogger2Cloud\test.py", line 73, in read_sensor_data
    ser.write(sdi_12_address + measurement_code + b"!")
  File "c:\Users\bnsoh2\Desktop\venvs\logger_env\Lib\site-packages\serial\serialwin32.py", line 317, in write
    raise SerialException("WriteFile failed ({!r})".format(ctypes.WinError()))
serial.serialutil.SerialException: WriteFile failed (PermissionError(13, 'Access is denied.', None, 5))
2023-08-04 16:19:10,728 [ERROR] - An error occurred: table sensor_data has no column named _5001A1TDR0623_ST
Traceback (most recent call last):
  File "c:\Users\bnsoh2\OneDrive - University of Nebraska-Lincoln\Documents\Coding Projects\Datalogger2Cloud\test.py", line 195, in <module>
    averaged_df.to_sql("sensor_data", conn, if_exists="append", index=False)
  File "c:\Users\bnsoh2\Desktop\venvs\logger_env\Lib\site-packages\pandas\core\generic.py", line 2878, in to_sql
    return sql.to_sql(
           ^^^^^^^^^^^
  File "c:\Users\bnsoh2\Desktop\venvs\logger_env\Lib\site-packages\pandas\io\sql.py", line 769, in to_sql
    return pandas_sql.to_sql(
           ^^^^^^^^^^^^^^^^^^
  File "c:\Users\bnsoh2\Desktop\venvs\logger_env\Lib\site-packages\pandas\io\sql.py", line 2379, in to_sql
    return table.insert(chunksize, method)
           ^^^^^^^^^^^^^^^^^^^^^^^^^^^^^^^
  File "c:\Users\bnsoh2\Desktop\venvs\logger_env\Lib\site-packages\pandas\io\sql.py", line 1023, in insert
    num_inserted = exec_insert(conn, keys, chunk_iter)
                   ^^^^^^^^^^^^^^^^^^^^^^^^^^^^^^^^^^^
  File "c:\Users\bnsoh2\Desktop\venvs\logger_env\Lib\site-packages\pandas\io\sql.py", line 2075, in _execute_insert
    conn.executemany(self.insert_statement(num_rows=1), data_list)
sqlite3.OperationalError: table sensor_data has no column named _5001A1TDR0623_ST
2023-08-08 11:04:29,713 [WARNING] - Compute Engine Metadata server unavailable on attempt 1 of 3. Reason: timed out
2023-08-08 11:04:32,715 [WARNING] - Compute Engine Metadata server unavailable on attempt 2 of 3. Reason: timed out
2023-08-08 11:04:35,723 [WARNING] - Compute Engine Metadata server unavailable on attempt 3 of 3. Reason: timed out
2023-08-08 11:04:35,723 [WARNING] - Authentication failed using Compute Engine authentication due to unavailable metadata server.
2023-08-08 11:08:22,812 [WARNING] - Compute Engine Metadata server unavailable on attempt 1 of 3. Reason: timed out
2023-08-08 11:08:25,815 [WARNING] - Compute Engine Metadata server unavailable on attempt 2 of 3. Reason: timed out
2023-08-08 11:08:28,824 [WARNING] - Compute Engine Metadata server unavailable on attempt 3 of 3. Reason: timed out
2023-08-08 11:08:28,824 [WARNING] - Authentication failed using Compute Engine authentication due to unavailable metadata server.
2023-08-09 07:04:15,697 [ERROR] - An error occurred: Error binding parameter 1: type 'Timestamp' is not supported
Traceback (most recent call last):
  File "c:\Users\bnsoh2\OneDrive - University of Nebraska-Lincoln\Documents\Coding Projects\Datalogger2Cloud\test.py", line 176, in <module>
    insert_data_to_db(averaged_df.to_dict(orient="records"))
  File "c:\Users\bnsoh2\OneDrive - University of Nebraska-Lincoln\Documents\Coding Projects\Datalogger2Cloud\database_functions.py", line 61, in insert_data_to_db
    cursor.executemany(insert_stmt, [tuple(row.values()) for row in data])
sqlite3.ProgrammingError: Error binding parameter 1: type 'Timestamp' is not supported
2023-08-09 07:12:12,154 [ERROR] - An error occurred: <class 'pandas._libs.tslibs.timestamps.Timestamp'>
Traceback (most recent call last):
  File "c:\Users\bnsoh2\OneDrive - University of Nebraska-Lincoln\Documents\Coding Projects\Datalogger2Cloud\test.py", line 176, in <module>
    schema = get_schema(averaged_df.to_dict(orient="records"))
             ^^^^^^^^^^^^^^^^^^^^^^^^^^^^^^^^^^^^^^^^^^^^^^^^^
  File "c:\Users\bnsoh2\OneDrive - University of Nebraska-Lincoln\Documents\Coding Projects\Datalogger2Cloud\gcloud_functions.py", line 83, in get_schema
    schema = [
             ^
  File "c:\Users\bnsoh2\OneDrive - University of Nebraska-Lincoln\Documents\Coding Projects\Datalogger2Cloud\gcloud_functions.py", line 84, in <listcomp>
    bigquery.SchemaField(field_name, type_mapping[type(sample_value)])
                                     ~~~~~~~~~~~~^^^^^^^^^^^^^^^^^^^^
KeyError: <class 'pandas._libs.tslibs.timestamps.Timestamp'>
2023-08-09 07:14:31,261 [ERROR] - An error occurred: [WinError 32] The process cannot access the file because it is being used by another process: 'C:\\Users\\bnsoh2\\AppData\\Local\\Temp\\tmpsdsww_q5'
Traceback (most recent call last):
  File "c:\Users\bnsoh2\OneDrive - University of Nebraska-Lincoln\Documents\Coding Projects\Datalogger2Cloud\test.py", line 178, in <module>
    update_bqtable(schema, table_name, averaged_df.to_dict(orient="records"))
  File "c:\Users\bnsoh2\OneDrive - University of Nebraska-Lincoln\Documents\Coding Projects\Datalogger2Cloud\gcloud_functions.py", line 138, in update_bqtable
    os.remove(temp_file_path)
PermissionError: [WinError 32] The process cannot access the file because it is being used by another process: 'C:\\Users\\bnsoh2\\AppData\\Local\\Temp\\tmpsdsww_q5'
2023-08-09 07:30:59,325 [ERROR] - An error occurred: 'list' object has no attribute 'items'
Traceback (most recent call last):
  File "c:\Users\bnsoh2\OneDrive - University of Nebraska-Lincoln\Documents\Coding Projects\Datalogger2Cloud\test.py", line 182, in <module>
    setup_database(schema, local_db)
  File "c:\Users\bnsoh2\OneDrive - University of Nebraska-Lincoln\Documents\Coding Projects\Datalogger2Cloud\database_functions.py", line 12, in setup_database
    [f"{col_name} {col_type}" for col_name, col_type in schema.items()]
                                                        ^^^^^^^^^^^^
AttributeError: 'list' object has no attribute 'items'
2023-08-09 14:01:53,487 [ERROR] - An error occurred: 'list' object has no attribute 'items'
Traceback (most recent call last):
  File "c:\Users\bnsoh2\OneDrive - University of Nebraska-Lincoln\Documents\Coding Projects\Datalogger2Cloud\test.py", line 182, in <module>
    setup_database(schema, local_db)
  File "c:\Users\bnsoh2\OneDrive - University of Nebraska-Lincoln\Documents\Coding Projects\Datalogger2Cloud\database_functions.py", line 12, in setup_database
    [f"{col_name} {col_type}" for col_name, col_type in schema.items()]
                                                        ^^^^^^^^^^^^
AttributeError: 'list' object has no attribute 'items'
2023-08-09 14:03:30,507 [ERROR] - An error occurred: <class 'pandas._libs.tslibs.timestamps.Timestamp'>
Traceback (most recent call last):
  File "c:\Users\bnsoh2\OneDrive - University of Nebraska-Lincoln\Documents\Coding Projects\Datalogger2Cloud\test.py", line 176, in <module>
    schema = get_schema(averaged_df.to_dict(orient="records"))
             ^^^^^^^^^^^^^^^^^^^^^^^^^^^^^^^^^^^^^^^^^^^^^^^^^
  File "c:\Users\bnsoh2\OneDrive - University of Nebraska-Lincoln\Documents\Coding Projects\Datalogger2Cloud\gcloud_functions.py", line 83, in get_schema
    schema = [
             ^
  File "c:\Users\bnsoh2\OneDrive - University of Nebraska-Lincoln\Documents\Coding Projects\Datalogger2Cloud\gcloud_functions.py", line 84, in <listcomp>
    bigquery.SchemaField(field_name, type_mapping[type(sample_value)])
                                     ~~~~~~~~~~~~^^^^^^^^^^^^^^^^^^^^
KeyError: <class 'pandas._libs.tslibs.timestamps.Timestamp'>
2023-08-09 14:09:20,570 [ERROR] - An error occurred: <class 'pandas._libs.tslibs.timestamps.Timestamp'>
Traceback (most recent call last):
  File "c:\Users\bnsoh2\OneDrive - University of Nebraska-Lincoln\Documents\Coding Projects\Datalogger2Cloud\test.py", line 185, in <module>
    insert_data_to_db(averaged_df.to_dict(orient="records"), local_db)
  File "c:\Users\bnsoh2\OneDrive - University of Nebraska-Lincoln\Documents\Coding Projects\Datalogger2Cloud\database_functions.py", line 47, in insert_data_to_db
    [
  File "c:\Users\bnsoh2\OneDrive - University of Nebraska-Lincoln\Documents\Coding Projects\Datalogger2Cloud\database_functions.py", line 48, in <listcomp>
    f"{col_name} {type_mapping[type(sample_value)]}"
                  ~~~~~~~~~~~~^^^^^^^^^^^^^^^^^^^^
KeyError: <class 'pandas._libs.tslibs.timestamps.Timestamp'>
